Workbook

Sheet data
A1: First name | B1: Surname | C1: Gender | D1: Religion | E1: Faculty | F1: Age ( In years) | G1: Category | H1: Board Marks (In %) | I1: Medium of Instruction | J1: Native State | K1: Native Place | L1: Fitness Level | M1: Hobbies | N1: Family Income | O1: Family Type | P1: Mode of Transportation | Q1: Food Habits | R1: Campus Habits | S1: Height (in cm only.) | T1: Weight (in kgs. only) | U1: 12th Board Group | V1: BMI
A2: Binal | B2: Barot | C2: Female | D2: Hindu | E2: Arts | F2: 20 | G2: SEBC | H2: 55 | I2: Gujarati | J2: Gujarat | K2: Vadodara | L2: A | M2: Playing | N2: > 600000 | O2: Nuclear | P2: O | Q2: Vegetarian | R2: Non - smoker | S2: 160 | T2: 39 | U2: Arts | V2: =T2/(S2/100)^2 -> 15.234375
A3: Dhara | B3: Bholani | C3: Female | D3: Hindu | E3: Science | F3: 21 | G3: General | H3: 80 | I3: Gujarati | J3: Gujarat | K3: Jamnagar | L3: N | M3: Writing | N3: 50000 - 150000 | O3: Joint | P3: O | Q3: Vegetarian | R3: Non - smoker | S3: 152 | T3: 50 | U3: A | V3: =T3/(S3/100)^2 -> 21.641274
A4: Tisha | B4: Chavda | C4: Female | D4: Hindu | E4: Arts | F4: 18 | G4: SEBC | H4: 63 | I4: Gujarati | J4: Gujarat | K4: Jamnagar | L4: N | M4: Listening Music | N4: > 600000 | O4: Nuclear | P4: V | Q4: Vegetarian | R4: Non - smoker | S4: 167 | T4: 74 | U4: Commerce | V4: =T4/(S4/100)^2 -> 26.533759
A5: PINAL | B5: DABHI | C5: Female | D5: Christian | E5: Science | F5: 22 | G5: SC | H5: 54 | I5: Gujarati | J5: Gujarat | K5: Vadodara | L5: N | M5: Movies | N5: 150000 - 300000 | O5: Joint | P5: V | Q5: Non - Vegetation | R5: Non - smoker | S5: 158 | T5: 42 | U5: A | V5: =T5/(S5/100)^2 -> 16.824227
A6: Vrutangi | B6: Dabhiya | C6: Female | D6: Hindu | E6: Arts | F6: 20 | G6: SEBC | H6: 65 | I6: English | J6: Gujarat | K6: Bharuch | L6: A | M6: Singing | N6: 50000 - 150000 | O6: Nuclear | P6: V | Q6: Vegetarian | R6: Non - smoker | S6: 162 | T6: 49 | U6: Arts | V6: =T6/(S6/100)^2 -> 18.670934
A7: Dhara | B7: Dave | C7: Female | D7: Hindu | E7: Arts | F7: 19 | G7: General | H7: 67 | I7: English | J7: Gujarat | K7: Vodadara | L7: N | M7: Travelling | N7: 50000 - 150000 | O7: Joint | P7: V | Q7: Vegetarian | R7: Non - smoker | S7: 166 | T7: 67 | U7: Commerce | V7: =T7/(S7/100)^2 -> 24.314124
A8: Priya | B8: Giri | C8: Female | D8: Hindu | E8: Commerce | F8: 22 | G8: General | H8: 69 | I8: English | J8: Gujarat | K8: Vadodara | L8: N | M8: Drawing | N8: 450000 - 600000 | O8: Nuclear | P8: B | Q8: Non - Vegetation | R8: Non - smoker | S8: 175 | T8: 73 | U8: Commerce | V8: =T8/(S8/100)^2 -> 23.836735
A9: Kaumudi | B9: Giridhar | C9: Female | D9: Hindu | E9: Science | F9: 21 | G9: General | H9: 86 | I9: English | J9: Maharashtra | K9: Nagpur | L9: N | M9: Katthak | N9: > 600000 | O9: Nuclear | P9: O | Q9: Vegetarian | R9: Non - smoker | S9: 163 | T9: 45 | U9: AB | V9: =T9/(S9/100)^2 -> 16.937032
A10: Riya | B10: Goswami | C10: Female | D10: Hindu | E10: Science | F10: 21 | G10: General | H10: 72 | I10: English | J10: Gujarat | K10: Vadodara | L10: N | M10: Dancing | N10: 450000 - 600000 | O10: Nuclear | P10: B | Q10: Non - Vegetation | R10: Non - smoker | S10: 167 | T10: 43 | U10: A | V10: =T10/(S10/100)^2 -> 15.418265
A11: KHUSHI | B11: JADHAV | C11: Female | D11: Hindu | E11: Arts | F11: 19 | G11: General | H11: 60 | I11: Gujarati | J11: Gujarat | K11: Vadodara | L11: N | M11: Travelling | N11: 450000 - 600000 | O11: Nuclear | P11: V | Q11: Non - Vegetation | R11: Non - smoker | S11: 152 | T11: 45 | U11: Arts | V11: =T11/(S11/100)^2 -> 19.477147
A12: Deepti | B12: Jakhotra | C12: Female | D12: Hindu | E12: Techo (Engineering) | F12: 21 | G12: SEBC | H12: 73.4 | I12: English | J12: Gujarat | K12: Somnath | L12: N | M12: Painting | N12: 150000 - 300000 | O12: Nuclear | P12: B | Q12: Vegetarian | R12: Non - smoker | S12: 158 | T12: 56 | U12: A | V12: =T12/(S12/100)^2 -> 22.432303
A13: Muskan | B13: Kacholia | C13: Female | D13: Hindu | E13: Arts | F13: 19 | G13: General | H13: 85 | I13: English | J13: Gujarat | K13: Kutch | L13: A | M13: Sports | N13: < 50000 | O13: Nuclear | P13: O | Q13: Vegetarian | R13: Non - smoker | S13: 165 | T13: 71 | U13: Commerce | V13: =T13/(S13/100)^2 -> 26.078972
... A116: Kishan | B116: Zaru | C116: Male | D116: Hindu | E116: Science | F116: 23 | G116: SEBC | H116: 75 | I116: English | J116: Gujarat | K116: Kutchh | L116: N | M116: Sports | N116: 50000 - 150000 | O116: Nuclear | P116: V | Q116: Vegetarian | R116: Non - smoker | S116: 173 | T116: 73 | U116: A | V116: =T116/(S116/100)^2 -> 24.391059

Sheet a-1
B2: QUESTION -1 | C2: find the percentage of boys and girls and draw a pie diagram.
C4: Row Labels | D4: Count of Gender
C5: Female | D5: 62
C6: Male | D6: 53
C7: Grand Total | D7: 115
B17: QUESTION -2 | C17: list out all those candidates with particular surname.
D19: AGRAWAL | E19: Ghaskata | F19: Kshatriya | G19: Panchal | H19: Pathak | I19: Roy | J19: Thaker
D20: YUVRAAJ | E20: Hardik | F20: Shipra | G20: Rutvik | H20: Manali | I20: Jayshree | J20: Riya
D21: badoliya | E21: Giri | F21: Kumar | G21: Sagar | H21: Pathan | I21: Sahu | J21: Tinwala
D22: Harsh | E22: Priya | F22: Anuj | G22: Smit | H22: Ayaz Khan | I22: Minakshi | J22: Mariyam
D23: Bariya | E23: Saksham | F23: Vishisht | G23: Pandya | H23: Patil | I23: Sarangthem | J23: Trivedi
D24: Sachin | E24: Giridhar | F24: Kumari | G24: Avani | H24: Aditi | I24: Banadso | J24: Nandini
D25: Barot | E25: Kaumudi | F25: Priya | G25: Parikh | H25: Pawar | I25: Savani | J25: Vagadia
D26: Binal | E26: Goswami | F26: Kureshi | G26: Riddhi | H26: Hemal | I26: Ashwini | J26: Rutvik
D27: Bhandari | E27: Riya | F27: Mahek | G27: Parmar | H27: Porwal | I27: Shah | J27: Vaghasiya
D28: Shubham | E28: Gupta | F28: Mali | G28: Amitkumar | H28: Meenakshi | I28: Mona | J28: Maitry
D29: Bholani | E29: Akshat | F29: Priyanka | G29: Dravid | H29: PRAJAPATI | I29: Zankruti | J29: Varankar
D30: Dhara | E30: Kartik | F30: Mansuri | G30: Hardiksinh | H30: KALPIT | I30: Shaikh | J30: Jatin
... D44: Dhara | E44: Siya | F44: Nair | G44: Vishva | H44: Soham | I44: Raval | J44: Nivetha Raju
E45: Km | F45: Praveen | H45: Rathore | I45: Suthar | J45: Zaru
E46: Yathidev | F46: Shruthi | H46: Yashasvi | I46: Kiran | J46: Kishan
F47: Srikanth | I47: Niyati
I48: Sushila
B50: QUESTION -3 | C50: List all the candidates according to the categories.
D52: General | E52: General | F52: General | G52: Other | H52: SC | I52: SEBC | J52: ST
D53: Aditi | E53: Jayesh | F53: Praveen | G53: Ashwini | H53: Kuldeep | I53: Ajay | J53: NEHA
D54: Aesha | E54: Jayshree | F54: Preetha | G54: Jatin | H54: Parth | I54: Binal | J54: Anuj
D55: Aiman | E55: Jenny | F55: Priya | G55: KALPIT | H55: PINAL | I55: Darren
D56: Ajay | E56: Jerry | F56: Priyanka | G56: Paresh | H56: Rohit | I56: Deepti
D57: Akshat | E57: Kartik | F57: Raval | G57: Soham | I57: Hardik
D58: Amitkumar | E58: Kartikey | F58: Riddhi | I58: Hardiksinh
D59: Anand Kumar | E59: Kaumudi | F59: Riya | I59: Kishan
D60: Anuj | E60: KHUSHI | F60: Riya | I60: Mahek
D61: Anupam | E61: Kiran | F61: Rutvik | I61: Mahek
D62: Arpit | E62: Komal | F62: Sagar | I62: Manthan
D63: Avani | E63: Kritina | F63: Saksham | I63: Minakshi
D64: Ayaz Khan | E64: Maitry | F64: Shipra | I64: Nikhil
D65: Ayushi | E65: Manali | F65: Shreya | I65: Niyati
D66: Banadso | E66: Manav | F66: Shruthi | I66: Pihu
D67: Bidyananda | E67: Mariyam | F67: Shruti | I67: Prakash
...

Sheet a-2
B3: QUESTION -1 | C3: List out all those male candidates who have scored between 60% and 70% and falls under ST category.
C5: No students belongs to ST category and scored between 60% and 70% in our dataset.
D7: All ST category Students are :
D8: Gender | E8: Board Marks (In %)
D9: Male | E9: 46
D10: Female | E10: 82
B13: QUESTION -2 | C13: List out all those male OBC candidates who have scored 60% and more and eat vegetarian foods, studies non-Commerce subjects.
D16: NAME | E16: SURNAME
D17: Manthan | E17: Darji
D18: Hardik | E18: Ghaskata
D19: Vishisht | E19: Kumar
D20: Rutvik | E20: Panchal
D21: Hardiksinh | E21: Parmar
D22: Prakash | E22: Ram
D23: Kishan | E23: Zaru
B26: QUESTION -3 | C26: List out all those English medium female candidates who are from General category and smokes in the campus, hailing from outside Baroda.
D28: No students belongs to English medium female candidates who are from General category and smokes in the campus, hailing from outside Baroda.
B31: QUESTION -4 | C31: List out all those male candidates who are vegetarians and whose family income is less than 5 lacs per annum and never sing.
D34: NAME | E34: SURNAME | G34: NAME | H34: SURNAME | J34: NAME | K34: SURNAME
D35: YUVRAAJ | E35: AGRAWAL | G35: Rutvik | H35: Panchal | J35: Raval | K35: Sujit
D36: Sachin | E36: Bariya | G36: Amitkumar | H36: Parmar | J36: Rutvik | K36: Vagadia
D37: Shubham | E37: Bhandari | G37: Hardiksinh | H37: Parmar | J37: Anuj | K37: Verma
D38: Manthan | E38: Darji | G38: Dravid | H38: Parmar | J38: Vinay | K38: Yadav
D39: Saksham | E39: Giri | G39: Mahek | H39: Parmar | J39: AJAY | K39: Yadav
D40: Akshat | E40: Gupta | G40: Dhrumil | H40: Patel | J40: Kishan | K40: Zaru
D41: Kartik | E41: Gupta | G41: Dipak | H41: Patel
D42: Vishisht | E42: Kumar | G42: KALPIT | H42: PRAJAPATI
D43: Kartikey | E43: Mishra | G43: Pradhyumansinh | H43: Puwar
D44: Jayesh | E44: Motiani | G44: Rahulkumar | H44: Rabari
D45: Srikanth | E45: Nair | G45: Prakash | H45: Ram
D46: Smit | E46: Panchal | G46: Hitendrasinh | H46: Rana
D47: Sagar | E47: Panchal | G47: Ajay | H47: Sharma
B50: QUESTION -5 | C50: List out all those candidates who belongs to ST category and have studied in Gujarati medium and whose family stays together, hailing from Ahmedabad.
D52: No students belongs to ST category and have studied in Gujarati medium and whose family stays together, hailing from Ahmedabad.
B55: QUESTION -6 | C55: Prepare a Multi-dimensional database table.
C57: FEMALE | I57: MALE
C58: VEGETARIANS | F58: NON-VEGETARIANS | I58: VEGETARIANS | L58: NON-VEGETARIANS
C59: ST/SC | D59: OBC | E59: GEN | F59: ST/SC | G59: OBC | H59: GEN | I59: ST/SC | J59: OBC | K59: GEN | L59: ST/SC | M59: OBC | N59: GEN
C60: 2 | D60: 7 | E60: 30 | F60: 1 | G60: 3 | H60: 19 | I60: 7 | J60: 2 | K60: 8 | L60: 1 | M60: 13 | N60: 22

Sheet a-3
B3: QUESTION -1 | C3: Establish correlations between all the continuous variables
C5: List of all continuous variables : | F5: Age , Board marks , Height , Weight
C7: VARIABLE - 1 | D7: VARIABLE - 2 | E7: Correlation coefficient
C8: Age | D8: Board marks | E8: =CORREL(data!F2:F116,data!H2:H116) -> 0.072088741
D9: Height | E9: =CORREL(data!S2:S116,data!F2:F116) -> 0.17401518
D10: Weight | E10: =CORREL(data!F2:F116,data!T2:T116) -> 0.041698461
C11: Board marks | D11: Height | E11: =CORREL(data!S2:S116,data!H2:H116) -> -0.011365971
D12: Weight | E12: =CORREL(data!H2:H116,data!T2:T116) -> -0.1549268
C13: Height | D13: Weight | E13: =CORREL(data!S2:S116,data!T2:T116) -> 0.43805832
B16: QUESTION -2 | C16: Fit a regression line of Weight on age and height and predict the weight when age = 20 and height = 165 cms.
C19: SUMMARY OUTPUT
C21: Regression Statistics
C22: Multiple R | D22: 0.43945952
C23: R Square | D23: 0.19312467
C24: Adjusted R Square | D24: 0.17871618
C25: Standard Error | D25: 12.927235
C26: Observations | D26: 115
C28: ANOVA
D29: df | E29: SS | F29: MS | G29: F | H29: Significance F
C30: Regression | D30: 2 | E30: 4479.8205 | F30: 2239.9103 | G30: 13.403535 | H30: 6.0417197e-06
C31: Residual | D31: 112 | E31: 18716.701 | F31: 167.1134
C32: Total | D32: 114 | E32: 23196.522
D34: Coefficients | E34: Standard Error | F34: t Stat | G34: P-value | H34: Lower 95% | I34: Upper 95% | J34: Lower 95.0% | K34: Upper 95.0%
C35: Intercept | D35: -42.246527 | E35: 26.213342 | F35: -1.6116422 | G35: 0.1098544 | H35: -94.184903 | I35: 9.6918492 | J35: -94.184903 | K35: 9.6918492
C36: Age ( In years) | D36: -0.39431732 | E36: 0.95446962 | F36: -0.41312715 | G36: 0.68030333 | H36: -2.2854765 | I36: 1.4968419 | J36: -2.2854765 | K36: 1.4968419
C37: Height (in cm only.) | D37: 0.66873667 | E37: 0.12974612 | F37: 5.1541941 | G37: 1.1058608e-06 | H37: 0.41166137 | I37: 0.92581197 | J37: 0.41166137 | K37: 0.92581197
C39: Y = Weight
C40: X1 = Age(in years)
C41: X2 = Height
C43: Weight = | D43: -42.25 - 0.39*Age + 0.67*Height
C44: = | D44: =D35+D36*20+D37*165 -> 60.208678
C46: predicted weight when age = 20 and height = 165 cms is 60.21
B48: QUESTION -3 | C48: Check the normality for BMI and study a goodness of fit test.
B70: QUESTION -4 | C70: Carry out a one sample z-test for testing mean height is 160 cms.
C72: std = | D72: 9.4349469
C74: Test | F74: Descriptive Statistics
C75: Null hypothesis | D75: H₀: μ = 160 | F75: N | G75: Mean | H75: StDev | I75: SE Mean | J75: 95% CI for μ
C76: Alternative hypothesis | D76: H₁: μ ≠ 160 | F76: 115 | G76: 163.678 | H76: 9.476 | I76: 0.88 | J76: (161.954, 165.403)
C77: Z-Value | D77: P-Value | F77: μ: population mean of Height (in cm only.)
C78: 4.18 | D78: 0 | F78: Known standard deviation = 9.43495
...

Sheet Sheet5
B3: Column Labels
B4: Female | K4: Female Total | L4: Male | V4: Male Total | W4: Grand Total
B5: Non - Vegetation | E5: Non - Vegetation Total | F5: Vegetarian | J5: Vegetarian Total | L5: Non - Vegetation | Q5: Non - Vegetation Total | R5: Vegetarian | U5: Vegetarian Total
B6: General | C6: SC | D6: SEBC | F6: General | G6: Other | H6: SEBC | I6: ST | L6: General | M6: Other | N6: SC | O6: SEBC | P6: ST | R6: General | S6: Other | T6: SEBC
A7: Count of Category | B7: 19 | C7: 1 | D7: 3 | E7: 23 | F7: 30 | G7: 1 | H7: 7 | I7: 1 | J7: 39 | K7: 62 | L7: 8 | M7: 3 | N7: 3 | O7: 2 | P7: 1 | Q7: 17 | R7: 22 | S7: 1 | T7: 13 | U7: 36 | V7: 53 | W7: 115
J11: Age ( In years) | K11: Height (in cm only.) | L11: Weight (in kgs. only)
J12: 20 | K12: 150 | L12: 70
J13: 19 | K13: 160 | L13: 84
J14: 21 | K14: 168 | L14: 45
J15: 20 | K15: 160 | L15: 39
J16: 22 | K16: 160 | L16: 63
J17: 21 | K17: 152 | L17: 50
J18: 22 | K18: 182 | L18: 59
J19: 18 | K19: 167 | L19: 74
J20: 18 | K20: 156 | L20: 90
J21: 22 | K21: 158 | L21: 42
J22: 20 | K22: 162 | L22: 49
J23: 21 | K23: 168 | L23: 58
... J126: 23 | K126: 173 | L126: 73
B133: =_xlfn.STDEV.P(data!S2:S116) -> 9.4349469
D150: RESIDUAL OUTPUT
D152: Observation | E152: Predicted Weight (in kgs. only) | F152: Residuals
D153: 1 | E153: 50.177628 | F153: 19.822372
D154: 2 | E154: 57.259312 | F154: 26.740688
D155: 3 | E155: 61.82057 | F155: -16.82057
D156: 4 | E156: 56.864994 | F156: -17.864994
D157: 5 | E157: 56.07636 | F157: 6.9236403
D158: 6 | E158: 51.120784 | F158: -1.1207836
D159: 7 | E159: 70.788567 | F159: -11.788567
D160: 8 | E160: 62.334786 | F160: 11.665214
D161: 9 | E161: 54.978682 | F161: 35.021318
D162: 10 | E162: 54.738886 | F162: -12.738886
D163: 11 | E163: 58.202468 | F163: -9.2024677
D164: 12 | E164: 61.82057 | F164: -3.8205704
... D267: 115 | E267: 64.375619 | F267: 8.6243809
